Workbook

Sheet PŘEHLED
A1: No. | B1: A / N | C1: ČÍSLO SML - ZZS SK | D1: ÚSEK | E1: DRUH | F1: NÁZEV FIRMY | G1: IČO | H1: NÁZEV SML | I1: POPIS SML | J1: PŘEDMĚT SML | K1: DATUM UZAVŘENÍ | L1: DATUM OD | M1: DATUM DO | N1: PERIODA | O1: HODNOTA | P1: UKONČENÍ | Q1: HODNOTA S DPH V RS | R1: ID REGISTR SMLUV | S1: DATUM ZVEŘEJNĚNÍ | T1: číslo jednací | U1: Upozornění před koncem smlouvy | V1: Kontrola | W1: Je smlouva v pořádku? | X1: Komentář oddělení VZ | Y1: KOMENTÁŘ ÚSEKU
A2: 1 | B2: N | C2: S-308/75030926/22 | D2: ÚŘe | E2: LICENCE | F2: Mgr. Lenka Daňková | G2: 76141227 | H2: Poskytnutí licence | I2: Smlouva o vytvoření uměleckého výkonu a poskytnutí licence | K2: 44872 | L2: 44872 | M2: 44956 | O2: 200 | P2: 44956
A3: 2 | B3: A | C3: S-029/75030926/22 | D3: ÚNLZP | E3: VÝPŮJČKA | F3: Krajské ředitelství policie Středočeského kraje | G3: 75151481 | H3: Smlouva o výpůjčce | I3: Smlouva o výpůjčce - 15 ks batohů vybavených AED | K3: 44603 | L3: 44603 | M3: 46063 | O3: 630000 | P3: 46063 | Q3: 630000 | R3: 17992883 | S3: 44603 | U3: 3 | V3: Ano
A4: 3 | B4: N | C4: S-361/75030926/22 | D4: ÚNLZP | E4: BEZÚPL. PŘEVOD | F4: Krajské ředitelství policie Středočeského kraje | G4: 75151481 | H4: Bezúplatný převod | I4: Smlouva o bezúplatném převodu vlastnictví_20ks masek ochranných chemických CM 6 | K4: 44894 | L4: 44894 | M4: 45386 | O4: 48556 | P4: 45386 | U4: 3 | V4: OK
A5: 4 | B5: N | C5: S-159/75030926/23 | D5: ÚPT | E5: BEZÚPL. PŘEVOD | F5: Krajské ředitelství policie Středočeského kraje | G5: 75151481 | H5: Bezúplatný převod | I5: Bezúplatný převod_sanitní automobil VW Transporter 3SY 7314 | K5: 45127 | L5: 45127 | M5: 45169 | O5: 55000 | P5: 45169 | V5: OK | W5: OK
A6: 5 | B6: N | C6: S-184/75030926/23 | D6: ÚNLZP | E6: SPOLUPRÁCE | F6: Krajské ředitelství policie Středočeského kraje | G6: 75151481 | H6: spolupráce | I6: Smlouva o spolupráci_sanitní vozidlo_prezentace techniky_Dětský den_9.6.2023 | K6: 45085 | L6: 45085 | M6: 45107 | P6: 45107 | U6: 3
A7: 6 | B7: N | C7: 133/75030926/18 | D7: ÚLé | E7: PRACOVNĚLÉKAŘSKÉ SLUŽBY | F7: MUDr. Jana Bačovská | G7: 75145774 | H7: závodní péče | I7: pracovnělékařské služby MUDr. Jana Bačovská | J7: Smlouva se závodním lékařem-dr.Bačovská | K7: 43251 | L7: 43252 | M7: 45443 | O7: 600 | P7: 45443 | Q7: 600 | R7: 5319791 | S7: 43252 | V7: OK | Y7: Ukončeno, pokračuje
A8: 7 | B8: N | C8: S-036/75030926/23 | D8: ÚNLZP | E8: STÁŽ | F8: MUDr. Helena Veselá | G8: 75095432 | H8: Zajištění praxe | I8: Smlouva o zajištění stáže_MUDr. Alena Štemberová_16.3.-2.4.2023 | K8: 44950 | L8: 44950 | M8: 45076 | O8: 3500 | P8: 45076
A9: 8 | B9: N | C9: S-068/75030926/22 | D9: ÚNLZP | E9: SPOLUPRÁCE | F9: Národní zemědělské muzeum, s.p.o. | G9: 75075741 | H9: spolupráce | I9: Smlouva o spolupráci_prezentace na Dni bezpečnosti_21.4.2022 | K9: 44657 | L9: 44657 | M9: 44673 | P9: 44673 | U9: 3
A10: 9 | B10: N | C10: S-122/75030926/23 | D10: ÚNLZP | E10: SPOLUPRÁCE | F10: Národní zemědělské muzeum, s.p.o. | G10: 75075741 | H10: spolupráce | I10: Smlouva o spolupráci_30.4.2023_sanitní vozidlo-Den bezpečnosti-Čáslav | K10: 45030 | L10: 45030 | M10: 45046 | P10: 45046
A11: 10 | B11: N | C11: S-282/75030926/22 | D11: ÚPT | E11: BEZÚPL. PŘEVOD | F11: Asociace TOM ČR, TOM 19195 TÁBORNÍCI | G11: 75045966 | H11: Bezúplatný převod | I11: Smlouva o bezúplatném převodu_JEEP GRAND CHEROKEE_7S3 9808 | K11: 44879 | L11: 44879 | M11: 44926 | P11: 44926 | V11: OK | W11: OK
A12: 11 | B12: N | C12: S-096/75030926/21 | D12: ÚNLZP | E12: DOZOR | F12: Základní škola a mateřská škola Všetaty - okres Mělník, příspěvková organizace | G12: 75033861 | H12: Zdravotnický dozor | I12: Zdravotnický dozor, 22.6.2021, Všetaty | K12: 44368 | L12: 44368 | M12: 44369 | O12: 0 | P12: 44369
A13: 12 | B13: N | C13: S-207/75030926/23 | D13: ÚNLZP | E13: SPOLUPRÁCE | F13: Základní škola a mateřská škola Všetaty - okres Mělník, příspěvková organizace | G13: 75033861 | H13: Smlouva o spolupráci | I13: Smlouva o spolupráci_sanitní vozidlo_prezentace techniky_15.6.2023 | K13: 45092 | L13: 45092 | M13: 45138 | P13: 45138
A14: 13 | B14: N | C14: S-137/75030926/22 | D14: ÚNLZP | E14: SPOLUPRÁCE | F14: Mateřská škola Pyšely, okres Benešov | G14: 75031671 | H14: Smlouva o spolupráci | I14: Smlouva o spolupráci_sanitní vozidlo_prezentace záchranářské techniky_MŠ Pyšely | K14: 44721 | L14: 44721 | M14: 44804 | P14: 44804
A15: 14 | B15: N | C15: S-149/75030926/23 | D15: ÚNLZP | E15: STÁŽ | F15: Zdravotnická záchranná služba Středočeského kraje, příspěvková organizace | G15: 75030926 | H15: Zajištění praxe | I15: Smlouva o zajištění stáže_MUDr. Michal Matoušek_4-12/2023 | K15: 45035 | L15: 45065 | M15: 45291 | P15: 45291
A16: 15 | B16: N | C16: S-117/75030926/22 | D16: ÚNLZP | E16: SPOLUPRÁCE | F16: Základní škola a Mateřská škola Kosova Hora | G16: 75030471 | H16: Smlouva o spolupráci | I16: Smlouva o spolupráci_sanitná vozidlo_prezentace techniky_"Ochrana člověka" | K16: 44704 | L16: 44704 | M16: 44804 | P16: 44804
A17: 16 | B17: N | C17: S-208/75030926/21 | D17: ÚPT | E17: PRONÁJEM | F17: Úřad práce České republiky | G17: 72496991 | H17: Pronájem | I17: nájem nebytových prostor Mnichovo Hradiště - ČR ÚP | K17: 44559 | L17: 44562 | M17: 45351 | O17: 119893 | P17: 45351 | Q17: 119893 | R17: 17564971 | S17: 44559 | V17: OK | W17: Ano
A18: 17 | B18: N | C18: S-207/75030926/21 | D18: ÚPT | E18: NÁJEM - DOHODA O UKONČENÍ | F18: Úřad práce České republiky | G18: 72496991 | H18: Dohoda o ukončení | I18: Dohoda o ukončení nájemní smlouvy č. 12/06/048 | K18: 44558 | L18: 44558 | M18: 44561 | O18: 1 | P18: 44561
A19: 18 | B19: N | C19: S-253/75030926/23 | D19: ÚNLZP | E19: SPOLUPRÁCE | F19: Úřad práce České republiky | G19: 72075805 | H19: Smlouva o spolupráci | I19: Smlouva o spolupráci_sanitní vozidlo_prezentace techniky_Den se složkami_9.9.23 | K19: 45174 | L19: 45174 | M19: 45199 | P19: 45199
A20: 19 | B20: N | C20: S-258/75030926/22 | D20: ÚNLZP | E20: SPOLUPRÁCE | F20: Úřad práce České republiky | G20: 72075805 | H20: Smlouva o spolupráci | I20: Smlouva o spolupráci_sanitní vozidlo"Den se složkami IZS"_24.9.2022 | K20: 44826 | L20: 44826 | M20: 44895 | P20: 44895
A21: 20 | B21: N | C21: S-355/75030926/23 | D21: ÚPT | E21: BEZÚPL. PŘEVOD | F21: Krajské ředitelství policie Pardubického kraje | G21: 72050250 | H21: bezúplatný převod | I21: SMLOUVA O BEZÚPLATNÉM PŘEVODU VLASTNICTVÍ MOVITÉ VĚCI_1E23217, 7A42038, 1AX4821 | K21: 45268 | L21: 45268 | M21: 45322 | O21: 163000 | P21: 45322 | Q21: 163000 | R21: 25153187 | S21: 45276 | V21: OK | W21: OK
A22: 21 | B22: N | C22: S-125/75030926/23 | D22: OIT | E22: SLUŽBY | F22: Krajské ředitelství policie Pardubického kraje | G22: 71799320 | H22: školení a konzultace | I22: Smlouva o provedení školení a konzultací | K22: 45065 | L22: 45065 | M22: 45795 | O22: 363000 | P22: 45795 | Q22: 363000 | R22: 22844323 | S22: 45065 | U22: 3 | Y22: kontaktní osoba byl MUDr. Matoušek, předpokládáme, že smluva by měla patřit pod ZOS
A23: 22 | B23: N | C23: S-104/75030926/21 | D23: ÚEko | E23: PRÁVNÍ SLUŽBY | F23: Mgr. Vladimír Kolář | G23: 71467114 | H23: Právní služby | I23: Právní služby_nemajetková újma | K23: 44396 | L23: 44396 | M23: 44561 | O23: 1 | P23: 44561
A24: 23 | B24: N | C24: S-115/75030926/21 | D24: ÚPer | E24: PRÁVNÍ SLUŽBY | F24: Mgr. Vladimír Kolář | G24: 71467114 | H24: právní služby | I24: právní služby ve věci ochrany dobrého jména | K24: 44391 | L24: 44391 | M24: 44500 | O24: 2000 | P24: 44500
A25: 24 | B25: N | C25: S-183/75030926/21 | D25: ÚPer | E25: PRÁVNÍ SLUŽBY | F25: Mgr. Vladimír Kolář | G25: 71467114 | H25: Právní služby | I25: Právní služby - zastoupení ve věci práv a povinností z dohody o spolupráci | K25: 44525 | L25: 44525 | M25: 44561 | O25: 1 | P25: 44561
A26: 25 | B26: N | C26: S-184/75030926/21 | D26: ÚPer | E26: PRÁVNÍ SLUŽBY | F26: Mgr. Vladimír Kolář | G26: 71467114 | H26: Právní služby | I26: Právní služby - zastoupení ve věci práv a povinností z dohody o spolupráci | K26: 44525 | L26: 44525 | M26: 44561 | O26: 1 | P26: 44561
A27: 26 | B27: N | C27: S-185/75030926/21 | D27: ÚPer | E27: PRÁVNÍ SLUŽBY | F27: Mgr. Vladimír Kolář | G27: 71467114 | H27: Právní služby | I27: Právní služby - zastoupení ve věci práv a povinností z dohody o spolupráci | K27: 44525 | L27: 44525 | M27: 44561 | O27: 1 | P27: 44561
A28: 27 | B28: A | C28: S-358/75030926/23 | D28: OIT | E28: PRÁVNÍ SLUŽBY | F28: Olejníček Jan, JUDr., advokát | G28: 71332111 | H28: Právní služby | I28: Smlouva o poskytování právních služeb_náhrada škody proti spol. TresTech s.r.o. | K28: 45279 | L28: 45279 | M28: 2958465 | O28: 0 | P28: 2958465 | R28: 25448523 | S28: 45305 | U28: 3 | V28: Ano | W28: NE, viz komentář | Y28: vyjádření p. Štěpána: v gesci ředitele
A29: 28 | B29: A | C29: S-359/75030926/23 | D29: OIT | E29: PRÁVNÍ SLUŽBY | F29: Olejníček Jan, JUDr., advokát | G29: 71332111 | H29: právní služby | I29: Sml o poskytování právních služeb_zamítnutí žádosti o poskytnutí dotace | K29: 45279 | L29: 45279 | M29: 2958465 | O29: 0 | P29: 2958465 | R29: 25448527 | S29: 45305 | U29: 3 | V29: Ano | W29: NE, viz komentář | Y29: vyjádření p. Štěpána: v gesci ředitele
A30: 29 | B30: A | C30: S-038/75030926/23 | D30: ÚPT | E30: NÁJEM | F30: MKSH, příspěvková organizace , Hostivice | G30: 71294023 | H30: Nájem nebyt.prostor | I30: Smlouva o nájmu nebytových prostor_Město Hostivice | K30: 44956 | L30: 44956 | M30: 46752 | N30: 1 | O30: 3624000 | P30: 46752 | X30: JEDNA A TA SAMÁ SMLOUVA POD DVĚMA ČÍSLY?
A31: 30 | B31: A | C31: S-317/75030926/22 | D31: ÚPT | E31: NÁJEM | F31: MKSH, příspěvková organizace , Hostivice | G31: 71294023 | H31: Nájem nebyt.prostor | I31: Smlouva o nájmu nebytových prostor_Město Hostivice | K31: 44591 | L31: 44956 | M31: 46752 | N31: 1 | O31: 3624000 | P31: 46752 | Q31: 3624000 | R31: 21675809 | S31: 44956
A32: 31 | B32: A | C32: S-357/75030926/22 | D32: ÚPT | E32: NÁJEM - DOHODA O NAROVNÁNÍ | F32: MKSH, příspěvková organizace , Hostivice | G32: 71294023 | H32: Dohoda o narovnání | I32: Dohoda o narovnání ke sml. o nájmu nebyt. prostor ze dne 1.9.2022_130/SPR/2020 | K32: 44911 | L32: 44911 | M32: 46752 | O32: 620000 | P32: 46752 | Q32: 620000 | R32: 21233469 | S32: 44914
A33: 32 | B33: A | C33: 019/75030926/17 | D33: ZOS | E33: VÝPŮJČKA - AED | F33: Generální ředitelství cel | G33: 71214011 | H33: Smlouva o výpůjčce | I33: výpůjčka 6x AED | J33: Smlouva o výpůčce-AED | K33: 42772 | L33: 42772 | M33: 46423 | O33: 235950 | P33: 46423 | Q33: 235950 | R33: 1113701 | S33: 42772
A34: 33 | B34: N | C34: S-263/75030926/22 | D34: ÚPT | E34: BEZÚPL. PŘEVOD | F34: Domov seniorů Nové Strašecí, poskytovatel sociálních služeb | G34: 71209921 | H34: Bezúplatný převod | I34: Bezúplatný převod_VW Transporter, RZ 9S5 0681 | K34: 44854 | L34: 44854 | P34: 44926 | V34: OK | W34: OK
A35: 34 | B35: A | C35: 16/06/127 | D35: ÚNLZP | E35: VÝPŮJČKA | F35: Záchranný sbor Česká republika - jednotka Náchod | G35: 71192255 | H35: Smlouva o výpůjčce | I35: výpůjčka 1x plicní ventilátor Medumat (UH1040082) 1x držák Life Base (D05040713) | J35: plicní ventilátor Medumat UH1040082 držá | K35: 42550 | L35: 42550 | M35: 46201 | O35: 0 | P35: 46201 | U35: 3 | V35: Ano
A36: 35 | B36: A | C36: S-056/75030926/20 | D36: ÚPT | E36: VÝPŮJČKA | F36: Záchranný sbor Česká republika - jednotka Náchod | G36: 71192255 | H36: Smlouva o výpůjčce | I36: Výpůjčka VW Transporter T5, RZ 9S5 0680 | J36: Výpůjčka VW Transporter T5, RZ 9S5 0680 | K36: 43916 | L36: 43916 | M36: 46106 | O36: 1 | P36: 46106 | R36: 11208472 | S36: 43916
A37: 36 | B37: N | C37: S-128/75030926/22 | D37: ÚNLZP | E37: SPOLUPRÁCE | F37: Mateřská škola Kouřim, okres Kolín příspěvková organizace | G37: 71009728 | H37: Smlouva o spolupráci | I37: Smlouva o spolupráci_sanitní vozidlo_prezentace záchranářské techniky | K37: 44714 | L37: 44714 | M37: 44804 | P37: 44804
A38: 37 | B38: N | C38: S-053/75030926/22 | D38: ÚNLZP | E38: SPOLUPRÁCE | F38: Základní škola Tuchlovice , okres Kladno | G38: 71002235 | H38: Smlouva o spolupráci | I38: Smlouva o spolupráci_prezentace záchranářské techniky při akci "Den s IZS" | K38: 44648 | L38: 44648 | M38: 44681 | O38: 0 | P38: 44681
A39: 38 | B39: N | C39: S-284/75030926/23 | D39: ÚNLZP | E39: SPOLUPRÁCE | F39: Základní škola a Mateřská škola Kolešovice, okres Rakovník | G39: 70946060 | H39: Zdravotnický dozor | I39: Smlouva o zajištění zdravotnického dozoru, 27.9.23, ZZS Rakovník | K39: 45195 | L39: 45196 | M39: 45196 | O39: 0 | P39: 45196
A40: 39 | B40: A | C40: 13/06/109 | D40: ÚNLZP | E40: SPOLUPRÁCE | F40: Pardubický kraj | G40: 70892822 | H40: Smlouva o spolupráci | I40: smlouva o spolupráci při poskytování ZZS | J40: smlouva o spolupráci při poskytování ZZS | K40: 41442 | L40: 41442 | M40: 2958465 | O40: 0 | P40: 2958465 | U40: 3 | V40: Ano
...

Sheet seznamy
B2: Úsek | C2: Měsíce | D2: Kontrolní | E2: Smlouva
B3: ÚŘe | C3: 3 | D3: Ano | E3: Ano
B4: ÚLé | C4: 6 | D4: Ne | E4: NE, viz komentář
B5: ÚNLZP | C5: 9
B6: ÚPer | C6: 12
B7: ÚEko
B8: ÚPT
B9: OIT
B10: ZOS
B11: PKP

Sheet ÚNLZP
B3: Číslo smlouvy | C3: Název | D3: IČO | E3: Partner | F3: Předpokládaná hodnota bez DPH | G3: Předpokládaná hodnota s DPH | H3: Platné do | J3: 2022 | M3: 2023 | P3: 2024 | S3: 2025 | V3: ZBÝVÁ
K4: bez DPH | L4: s DPH | N4: bez DPH | O4: s DPH | Q4: bez DPH | R4: s DPH | T4: bez DPH | U4: s DPH | V4: bez DPH | W4: s DPH
B5: S-080/75030926/23 | C5: BTK, Servis a náhradní díly pro defibrilátory Corpuls 3 | D5: 27094987 | E5: Cheirón, a.s. | F5: 1000080 | G5: 1210096.8 | H5: 46455 | M5: 45196 | N5: 13800 | O5: 16698 | P5: 45348 | Q5: 7520 | R5: 9099.2 | S5: 45890 | T5: =8349*100/121 -> 6900 | U5: 8349 | V5: =SUM(F5-N17-Q17-T17) -> 420037.41 | W5: =SUM(G5-O17-R17-U17) -> 508245.26
M6: 45198 | N6: 13800 | O6: 16698 | P6: 45554 | Q6: 6900 | R6: 8349 | S6: 45927 | T6: =U6*100/121 -> 29460 | U6: 35646.6
M7: 45198 | N7: 6900 | O7: 8349 | P7: 45554 | Q7: 20700 | R7: 25047 | S7: 45932 | T7: =U7*100/121 -> 59600 | U7: 72116
M8: 45198 | N8: 6900 | O8: 8349 | P8: 45554 | Q8: 6900 | R8: 8349 | S8: 45952 | T8: =U8*100/121 -> 22560 | U8: 27297.6
M9: 45198 | N9: 13800 | O9: 16698 | P9: 45554 | Q9: 6900 | R9: 8349
M10: 45224 | N10: 6900 | O10: 8349 | P10: 45554 | Q10: 6900 | R10: 8349
M11: 45224 | N11: 6900 | O11: 8349 | P11: 45561 | Q11: 20700 | R11: 25047
M12: 45224 | N12: 6900 | O12: 8349 | P12: 45561 | Q12: 20700 | R12: 25047
M13: 45225 | N13: 6900 | O13: 8349 | P13: 45586 | Q13: =16698*100/121 -> 13800 | R13: 16698
M14: 45239 | N14: 379322.59 | O14: 458980.34
I17: Celkem | N17: =SUM(N5:N16) -> 462122.59 | O17: =SUM(O5:O16) -> 559168.34 | Q17: =SUM(Q5:Q16) -> 111020 | R17: =SUM(R5:R16) -> 134334.2 | T17: 6900 | U17: 8349
B18: S-269/75030926/2025 | C18: Batohy pro výjezdové skupiny ZZS SK – část A | D18: 60719044 | E18: Vakuform, s.r.o. | F18: 850000 | G18: 1028500 | H18: 46470 | V18: =SUM(F18-N30-Q30-T30) -> 850000 | W18: =SUM(G18-O30-R30-U30) -> 1028500
I30: Celkem | N30: =SUM(N18:N29) -> 0 | O30: =SUM(O18:O29) -> 0 | Q30: =SUM(Q18:Q29) -> 0 | R30: =SUM(R18:R29) -> 0 | T30: 0 | U30: 0
B31: S-270/75030926/2025 | C31: Batohy pro výjezdové skupiny ZZS SK – část B | D31: 60719044 | E31: Vakuform, s.r.o. | F31: 500000 | G31: 605000 | H31: 46470 | V31: =SUM(F31-N43-Q43-T43) -> 500000 | W31: =SUM(G31-O43-R43-U43) -> 605000
I43: Celkem | N43: =SUM(N31:N42) -> 0 | O43: =SUM(O31:O42) -> 0 | Q43: =SUM(Q31:Q42) -> 0 | R43: =SUM(R31:R42) -> 0 | T43: 0 | U43: 0
B44: S-265/75030926/24 | C44: Dezinfekce II. | D44: 48586285 | E44: B. Braun Medical s.r.o. | F44: 1500000 | G44: 1815000 | H44: 46252 | P44: 45597 | Q44: =80311.89*100/121 -> 66373.463 | R44: 80311.89 | S44: 45737 | T44: =93248*100/121 -> 77064.463 | U44: 93248 | V44: =SUM(F44-Q62-T62) -> 1001598.2 | W44: =SUM(G44-R62-U62) -> 1211934.7
P45: 45624 | Q45: 490 | R45: 592 | S45: 45737 | T45: =2147.75*100/121 -> 1775 | U45: 2147.75
P46: 45632 | Q46: =9073*100/121 -> 7498.3471 | R46: =1512.5+7560.5 -> 9073 | S46: 45741 | T46: =8046.5*100/121 -> 6650 | U46: 8046.5
P47: 45646 | Q47: =99416.32*100/121 -> 82162.248 | R47: 99416.32 | S47: 45743 | T47: =1911.8*100/121 -> 1580 | U47: 1911.8
P48: 45649 | Q48: =8814.85*100/121 -> 7285 | R48: 8814.85 | S48: 45757 | T48: =592.9*100/121 -> 490 | U48: 592.9
S49: 45792 | T49: =19432.6*100/121 -> 16060 | U49: 19432.6
S50: 45793 | T50: =8094.9*100/121 -> 6690 | U50: 8094.9
S51: 45852 | T51: =U51*100/121 -> 65174.463 | U51: 78861.1
S52: 45897 | T52: =U52*100/121 -> 45919.463 | U52: 55562.55
S53: 45910 | T53: =U53*100/121 -> 3160 | U53: 3823.6
S54: 45925 | T54: =U54*100/121 -> 6690 | U54: 8094.9
S55: 45933 | T55: =U55*100/121 -> 6650 | U55: 8046.5
S56: 45945 | T56: =U56*100/121 -> 47205.678 | U56: 57118.87
S57: 45950 | T57: =U57*100/121 -> 245 | U57: 296.45
S58: 46019 | T58: =U58*100/121 -> 49238.678 | U58: 59578.8
I62: Celkem | Q62: =SUM(Q44:Q61) -> 163809.06 | R62: =SUM(R44:R61) -> 198208.06 | T62: =SUM(T44:T61) -> 334592.74 | U62: =SUM(U44:U61) -> 404857.22
B63: S-265/75030926/22 | C63: Fixační límce | D63: 27094987 | E63: Cheirón, a.s. | F63: 750000 | G63: 907500 | H63: 46299 | J63: 44881 | K63: 56973.6 | L63: 68938.06 | M63: 45009 | N63: 52225.8 | O63: 63193.22 | P63: 45336 | Q63: 52225.8 | R63: 58492.9 | S63: 45713 | T63: 30052.8 | U63: 33659.14 | V63: =SUM(F63-K69-N69-Q69-T69) -> 332307.83 | W63: =SUM(G63-L69-O69-R69-U69) -> 420429.14
M64: 45189 | N64: 52225.8 | O64: 63193.22 | P64: 45457 | Q64: 37982.4 | R64: 42540.29 | S64: 45838 | T64: 30052.8 | U64: 33659.14
P65: 45561 | Q65: 31722.4 | R65: 35529.09 | S65: 45883 | T65: =U65/121*100 -> 28650.529 | U65: 34667.14
P66: 45643 | Q66: 21704.8 | R66: 24309.38 | S66: 45993 | T66: =U66/121*100 -> 23875.438 | U66: 28889.28
I69: Celkem | K69: 56973.6 | L69: 68938.06 | N69: =SUM(N63:N68) -> 104451.6 | O69: =SUM(O63:O68) -> 126386.44 | Q69: =SUM(Q63:Q68) -> 143635.4 | R69: =SUM(R63:R68) -> 160871.66 | T69: =SUM(T63:T68) -> 112631.57 | U69: =SUM(U63:U68) -> 130874.7
B70: S-241/75030926/24 | C70: Gravitační infuzní sety | D70: 27529053 | E70: POLYMED medical CZ, a.s. | F70: 700000 | G70: 784000 | H70: 46221 | P70: 45511 | Q70: 32400 | R70: 36288 | S70: 45779 | T70: 40500 | U70: 45360 | V70: =SUM(F70-Q78-T78) -> 319300 | W70: =SUM(G70-R78-U78) -> 357616
P71: 45554 | Q71: 40500 | R71: 45360 | S71: 45847 | T71: 40500 | U71: 45360
...

Sheet ÚEko
B3: Číslo smlouvy | C3: Název | D3: IČO | E3: Partner | F3: Předpokládaná hodnota bez DPH | G3: Předpokládaná hodnota s DPH | H3: Platné do | J3: 2022 | M3: 2023 | P3: 2024 | S3: 2025 | V3: ZBÝVÁ
B4: Účetnictví a rozpočet | K4: bez DPH | L4: s DPH | N4: bez DPH | O4: s DPH | Q4: bez DPH | R4: s DPH | T4: bez DPH | U4: s DPH | V4: bez DPH | W4: s DPH
B5: S-147/75030926/23 | C5: Smlouva o poskytování poradenských a konzultačních služeb | D5: 29268931 | E5: Alter Audit, s.r.o. | F5: 500000 | G5: 605000 | H5: 46022 | M5: 45167 | N5: 86400 | O5: 104544 | P5: 45324 | Q5: 46800 | R5: 56628 | S5: 45664 | T5: 33300 | U5: 40293 | V5: =SUM(F5-N12-Q12-T12) -> 73400 | W5: =SUM(G5-O12-R12-U12) -> 88814
M6: 45271 | N6: 55800 | O6: 67518 | P6: 45351 | Q6: 26100 | R6: 31581 | S6: 45751 | T6: 77400 | U6: 93654
P7: 45377 | Q7: 28800 | R7: 34848 | S7: 45847 | T7: 27900 | U7: 33759
S8: 45926 | T8: 44100 | U8: 53361
I12: Celkem | N12: 142200 | O12: 172062 | Q12: =SUM(Q5:Q11) -> 101700 | R12: =SUM(R5:R11) -> 123057 | T12: =SUM(T5:T11) -> 182700 | U12: =SUM(U5:U11) -> 221067
B13: S-134/75030926/2025 | C13: Smlouva na služby_Podpora při nastavení a vedení účetních procesů | D13: 18383084 | E13: ALFIN servis, s.r.o. | F13: 600000 | G13: 726000 | H13: 46506 | S13: 45883 | T13: =U13*100/121 -> 7665.2893 | U13: 9275 | V13: =SUM(F13-Q22-T22) -> 516809.71 | W13: =SUM(G13-R22-U22) -> 625339.75
S14: 45890 | T14: =U14*100/121 -> 16800 | U14: 20328
S15: 45933 | T15: 7350 | U15: 8893.5
S16: 45971 | T16: 12600 | U16: 15246
S17: 45982 | T17: 13475 | U17: 16304.75
S18: 46010 | T18: 25300 | U18: 30613
I22: Celkem | T22: =SUM(T13:T21) -> 83190.289 | U22: =SUM(U13:U21) -> 100660.25
B23: S-211/75030926/2025 | C23: Smlouva na služby_Audit účetních závěrek ZZS SK 2025 a 2026 | D23: 25699032 | E23: HZConsult s.r.o. | F23: 1000000 | G23: 1210000 | H23: 46575 | V23: =SUM(F23-Q27) -> 1000000 | W23: =SUM(G23-R27) -> 1210000
I27: Celkem
B28: S-221/75030926/2025 | C28: Smlouva na služby_zpracování přiznání k dani z příjmů PO a daň. porad. 2025/2026 | D28: 9275525 | E28: Moore Accounting CZ, s.r.o. | F28: 750000 | G28: 907500 | H28: 46575 | S28: 45910 | T28: =U28*100/121 -> 3200 | U28: 3872 | V28: =SUM(F28-Q35-T35) -> 724800 | W28: =SUM(G28-R35-U35) -> 877008
S29: 45969 | T29: =U29*100/121 -> 6400 | U29: 7744
S30: 46001 | T30: 15600 | U30: 18876
I35: Celkem | T35: =SUM(T28:T34) -> 25200 | U35: =SUM(U28:U34) -> 30492
B37: Odd. pojišťoven
B39: S-248/75030926/24 | C39: Smlouva o poskytování konzultačních a dalších souvisejících služeb | D39: 26746131 | E39: KTTP, s.r.o. | F39: 150000 | G39: 181500 | H39: 46022 | P39: 45565 | Q39: 45625 | R39: 55206.3 | S39: 45743 | T39: 7031.25 | U39: 8507.81 | V39: =SUM(F39-Q43-T43) -> 38593.688 | W39: =SUM(G39-R43-U43) -> 46698.28
P40: 45597 | Q40: =7940.7*100/121 -> 6562.562 | R40: 7940.7 | S40: 45959 | T40: 35156.25 | U40: 42539.06
P41: 45624 | Q41: 17031.25 | R41: 20607.85
I43: Celkem | Q43: =SUM(Q39:Q42) -> 69218.812 | R43: =SUM(R39:R42) -> 83754.85 | T43: =SUM(T39:T42) -> 42187.5 | U43: =SUM(U39:U42) -> 51046.87
B44: S-279/75030926/2025 | C44: Dohoda o uznání dluhu a způsobu jeho placení | D44: 49516736 | E44: ZS ASČR Kralupy | G44: 770230 | H44: 46142 | S44: 45996 | U44: 100000 | W44: =SUM(G44-R48-U48) -> 670230
I48: Celkem | Q48: =SUM(Q44:Q47) -> 0 | R48: =SUM(R44:R47) -> 0 | T48: =SUM(T44:T47) -> 0 | U48: =SUM(U44:U47) -> 100000
B51: Odd. VZ
B53: S-096/75030926/22 | C53: Rámcová smlouva o poskytnutí právních služeb_administrace VZ | D53: 5732069 | E53: KAROLAS Legal s.r.o., advokátní kancelář | F53: 490000 | G53: 592900 | H53: 45657 | P53: 45503 | Q53: =71995*100/121 -> 59500 | R53: 71995 | S53: 46019 | T53: 135000 | U53: 163350 | V53: =SUM(F53-Q57-T57) -> 295500 | W53: =SUM(G53-R57-U57) -> 357405
I57: Celkem | Q57: =SUM(Q53:Q56) -> 59500 | R57: =SUM(R53:R56) -> 71995 | T57: 135000 | U57: 163500
B58: S-016/75030926/2025 | C58: Rámcová smlouva_Poskytování advokátních služeb III. | D58: 5732069 | E58: KAROLAS Legal s.r.o., advokátní kancelář | F58: 2000000 | G58: 2420000 | H58: 46781 | S58: 45757 | T58: 55800 | U58: 67518 | V58: =SUM(F58-Q91-T91) -> 776200 | W58: =SUM(G58-R91-U91) -> 939202.5
S59: 45784 | T59: 13500 | U59: 16335
S60: 45821 | T60: 109800 | U60: 132858
S61: 45847 | T61: 88200 | U61: 106722
S62: 45875 | T62: 51750 | U62: 62617.5
S63: 45910 | T63: 26100 | U63: 31581
S64: 45944 | T64: 60300 | U64: 72963
S65: 45968 | T65: 69750 | U65: 84397.5
S66: 45968 | T66: 44550 | U66: 53905.5
S67: 45976 | T67: 70200 | U67: 84942
...

Sheet ÚLé
B3: Číslo smlouvy | C3: Název | D3: IČO | E3: Partner | F3: Předpokládaná hodnota bez DPH | G3: Předpokládaná hodnota s DPH | H3: Platné do | J3: 2023 | M3: 2024 | P3: 2025 | S3: ZBÝVÁ
K4: bez DPH | L4: s DPH | N4: bez DPH | O4: s DPH | Q4: bez DPH | R4: s DPH | S4: bez DPH | T4: s DPH
B5: S-250/75030926/2025 | C5: Rámcová dohoda_Infuzní roztoky IV_část A | D5: 48586285 | E5: B. Braun Medical s.r.o. | F5: 354879 | G5: 397464.48 | H5: 46606 | P5: 45932 | Q5: =R5/112*100 -> 25537 | R5: 28601.44 | S5: =SUM(F5-K21-N21-Q21) -> 287655.63 | T5: =SUM(G5-L21-O21-R21) -> 322174.31
P6: 45951 | Q6: =R6/112*100 -> 11586.098 | R6: 12976.43
P7: 45987 | Q7: =R7/112*100 -> 21838.679 | R7: 24459.32
P8: 46022 | Q8: =R8/112*100 -> 8261.5893 | R8: 9252.98
I21: Celkem | K21: =SUM(K5:K20) -> 0 | L21: =SUM(L5:L20) -> 0 | N21: =SUM(N5:N20) -> 0 | O21: =SUM(O5:O20) -> 0 | Q21: =SUM(Q5:Q20) -> 67223.366 | R21: =SUM(R5:R20) -> 75290.17
B22: S-249/75030926/2025 | C22: Rámcová dohoda_Infuzní roztoky IV_část B | D22: 49689011 | E22: Baxter Czech spol. s r.o. | F22: 2328591 | G22: 2608021.9 | H22: 46606 | P22: 45947 | Q22: =R22*100/112 -> 237625.2 | R22: 266140.22 | S22: =SUM(F22-K38-N38-Q38) -> 1896259.8 | T22: =SUM(G22-L38-O38-R38) -> 2123811
P23: 46010 | Q23: =R23*100/112 -> 194706.01 | R23: 218070.73
I38: Celkem | K38: =SUM(K22:K37) -> 0 | L38: =SUM(L22:L37) -> 0 | N38: =SUM(N22:N37) -> 0 | O38: =SUM(O22:O37) -> 0 | Q38: =SUM(Q22:Q37) -> 432331.21 | R38: =SUM(R22:R37) -> 484210.95
B39: S-252/75030926/24 | C39: Léky III. | D39: 25277961 | E39: Interpharmac s.r.o. | F39: 5400000 | G39: 6048000 | H39: 46247 | M39: 45554 | N39: =56766.83*100/112 -> 50684.67 | O39: 56766.83 | P39: 45664 | Q39: =R39*100/112 -> 65645.679 | R39: 73523.16 | S39: =SUM(F39-N84-Q84) -> 1160380 | T39: =SUM(G39-O84-R84) -> 1299625.6
M40: 45561 | N40: =109264.17*100/112 -> 97557.295 | O40: 109264.17 | P40: 45667 | Q40: =R40*100/112 -> 55351.527 | R40: 61993.71
M41: 45579 | N41: =101621.41*100/112 -> 90733.402 | O41: 101621.41 | P41: 45685 | Q41: =R41*100/112 -> 68102.42 | R41: 76274.71
M42: 45594 | N42: =134316.2*100/112 -> 119925.18 | O42: 134316.2 | P42: 45699 | Q42: =R42*100/112 -> 146488.37 | R42: 164066.97
M43: 45611 | N43: =158843.72*100/112 -> 141824.75 | O43: 158843.72 | P43: 45713 | Q43: =R43*100/112 -> 31941.679 | R43: 35774.68
M44: 45624 | N44: =185854.1*100/112 -> 165941.16 | O44: 185854.1 | P44: 45715 | Q44: =R44*100/112 -> 32305.232 | R44: 36181.86
M45: 45637 | N45: =160458.3*100/112 -> 143266.34 | O45: 160458.3 | P45: 45742 | Q45: =R45*100/112 -> 249266.04 | R45: 279177.96
M46: 45646 | N46: =95903.26*100/112 -> 85627.911 | O46: 95903.26 | P46: 45776 | Q46: =R46*100/112 -> 343525.68 | R46: 384748.76
M47: 45649 | N47: =79804.57*100/112 -> 71254.08 | O47: 79804.57 | P47: 45784 | Q47: =R47*100/112 -> 82111.625 | R47: 91965.02
P48: 45804 | Q48: =R48*100/112 -> 71964.33 | R48: 80600.05
P49: 45793 | Q49: =R49*100/112 -> 47364.259 | R49: 53047.97
P50: 45807 | Q50: =R50*100/112 -> 41974.598 | R50: 47011.55
P51: 45818 | Q51: =R51*100/112 -> 40982.339 | R51: 45900.22
P52: 45821 | Q52: =R52*100/112 -> 65934.348 | R52: 73846.47
P53: 45832 | Q53: =R53*100/112 -> 53567.911 | R53: 59996.06
P54: 45835 | Q54: =R54*100/112 -> 43753.259 | R54: 49003.65
P55: 45847 | Q55: =R55*100/112 -> 31057.795 | R55: 34784.73
P56: 45847 | Q56: =R56*100/112 -> 20202.527 | R56: 22626.83
P57: 45853 | Q57: =R57*100/112 -> 91910.312 | R57: 102939.55
P58: 45868 | Q58: =R58*100/112 -> 17506.545 | R58: 19607.33
P59: 45873 | Q59: =R59*100/112 -> 95622.723 | R59: 107097.45
... P81: 46022 | Q81: =R81*100/112 -> 44810.018 | R81: 50187.22
I84: Celkem | N84: =SUM(N39:N83) -> 966814.79 | O84: =SUM(O39:O83) -> 1082832.6 | Q84: =SUM(Q39:Q83) -> 3272805.2 | R84: =SUM(R39:R83) -> 3665541.8
I89: Celkem
I94: Celkem
B99: Vyčerpané/skončené smlouvy
B101: S-145/75030926/23 | C101: Infuzní roztoky II. | D101: 19010290 | E101: Pharmos, a.s. | F101: 1990000 | G101: 2407900 | H101: 45830 | J101: 45168 | K101: 97747.18 | L101: 118274.09 | M101: 45317 | N101: =109338.51*100/121 -> 90362.405 | O101: 109338.51 | P101: 45663 | Q101: =19981.38/121*100 -> 16513.537 | R101: 19981.38 | S101: =SUM(F101-K117-N117-Q117) -> 187217.09 | T101: =SUM(G101-L117-O117-R117) -> 226532.66
J102: 45198 | K102: 83723.85 | L102: 101305.86 | M102: 45350 | N102: =7346.94*100/121 -> 6071.8512 | O102: 7346.94 | P102: 45686 | Q102: =117286.79/121*100 -> 96931.231 | R102: 117286.79
B103: skončeno | J103: 45229 | K103: 78840.32 | L103: 95396.79 | M103: 45351 | N103: =70924.73*100/121 -> 58615.479 | O103: 70924.73 | P103: 45715 | Q103: =75864.65/121*100 -> 62698.058 | R103: 75864.65
J104: 45260 | K104: 80120.79 | L104: 96946.16 | M104: 45379 | N104: =61114.09*100/121 -> 50507.512 | O104: 61114.09 | P104: 45716 | Q104: =13618.73/121*100 -> 11255.149 | R104: 13618.73
...

Sheet ÚPer
B3: Číslo smlouvy | C3: Název | D3: IČO | E3: Partner | F3: Předpokládaná hodnota bez DPH | G3: Předpokládaná hodnota s DPH | H3: Platné do | J3: 2023 | M3: 2024 | P3: 2025 | S3: ZBÝVÁ
K4: bez DPH | L4: s DPH | N4: bez DPH | O4: s DPH | Q4: bez DPH | R4: s DPH | S4: bez DPH | T4: s DPH
A5: 1 | B5: S-224/75030926/24 | C5: Benefitní program pro zaměstnance_Multisport | D5: 24715299 | E5: MultiSport Benefit, s.r.o. | G5: 864000 | H5: 46934 | M5: 45541 | O5: 53800 | P5: 45670 | R5: 68340 | T5: =(O19+R19) -> 1179940
M6: 45568 | O6: 54580 | P6: 45699 | R6: 66420 | S6: celkem uhrazeno
M7: 45601 | O7: 63860 | P7: 45727 | R7: 68980
M8: 45631 | O8: 67380 | P8: 45755 | R8: 75240
P9: 45783 | R9: 76200
P10: 45820 | R10: 77100
P11: 45847 | R11: 78120
P12: 45875 | R12: 79080
P13: 45903 | R13: 82600
P14: 45937 | R14: 85480
P15: 45966 | R15: 89460
P16: 46000 | R16: 93300
I19: Celkem | O19: =SUM(O5:O18) -> 239620 | R19: =SUM(R5:R18) -> 940320
A20: 2 | B20: S-086/75030926/2025 | C20: Smlouva na právní služby_rovné odměňování zaměstnanců | D20: 29055130 | E20: Deloitte Legal s.r.o. | F20: 750000 | G20: =750000*121/100 -> 907500 | P20: 45835 | Q20: 128000 | R20: 154880 | S20: =F20-Q32 -> 7600 | T20: =G20-R32 -> 9196
P21: 45925 | Q21: =R21/121*100 -> 89600 | R21: 108416
P25: obj. 9.12.2025 | Q25: 96000 | R25: =Q25*1.21 -> 116160
P26: obj. 8.12.2025 | Q26: 76800 | R26: =Q26*1.21 -> 92928
P27: obj 20.11.2025 | Q27: 64000 | R27: =Q27*1.21 -> 77440
P28: obj 11.11.2025 | Q28: 16000 | R28: =Q28*1.21 -> 19360
P29: obj 7.11.2025 | Q29: 80000 | R29: =Q29*1.21 -> 96800
P30: obj 6.11.2025 | Q30: 160000 | R30: =Q30*1.21 -> 193600
P31: obj 24.10.2025 | Q31: 32000 | R31: =32000*1.21 -> 38720
K32: 0 | L32: 0 | N32: 0 | O32: 0 | Q32: =SUM(Q20:Q31) -> 742400 | R32: =SUM(R20:R31) -> 898304
A33: 3 | B33: S-148/75030926/2025 | C33: Smlouva na služby_poskytování právních služeb_Soudní jednání _Marcela Uličná | D33: 29055130 | E33: Deloitte Legal s.r.o. | F33: 67200 | G33: 81312 | P33: 45855 | Q33: 67200 | R33: 81312
I37: Celkem | Q37: 67200 | R37: 81312
A38: 4 | B38: S-384/75030926/2025 | C38: Smlouva na právní služby_poradenství v oblasti pracovního práva | D38: 29055130 | E38: Deloitte Legal s.r.o. | F38: 1500000 | G38: =1500000*1.21 -> 1815000 | S38: =F38-Q47 -> 1436000 | T38: =G38-R47 -> 1737560
P46: OBJ. 15.12. | Q46: 64000 | R46: =Q46*1.21 -> 77440
I47: Celkem | Q47: 64000 | R47: 77440
A48: 5
I56: Celkem

Sheet ÚPT
B3: Číslo smlouvy | C3: Název | D3: IČO | E3: Partner | F3: Předpokládaná hodnota bez DPH | G3: Předpokládaná hodnota s DPH | H3: Platné do | J3: 2022 | M3: 2023 | P3: 2024 | S3: 2025 | W3: ZBÝVÁ
K4: bez DPH | L4: s DPH | N4: bez DPH | O4: s DPH | Q4: bez DPH | R4: s DPH | T4: číslo fa | U4: bez DPH | V4: s DPH | W4: bez DPH | X4: s DPH
B5: S-283/75030926/24 | C5: Pneu, autodíly, autodoplňky, servisní služby | D5: 41193598 | E5: BestDrive Czech Republic, s.r.o. | F5: 50000 | G5: 60500 | H5: 47349 | S5: 45951 | T5: 2000888050 | U5: =V5/1.21 -> 616.24793 | V5: 745.66 | W5: =F5-U31 -> 30879.62 | X5: =G5-V31 -> 36732.84
S6: 45981 | T6: 2000911239 | U6: =V6/1.21 -> 1704.2479 | V6: 2062.14
S7: 45741 | T7: 2000824009 | U7: =V7/1.21 -> 616.24793 | V7: 745.66
S8: 45741 | T8: 2000824010 | U8: =V8/1.21 -> 616.24793 | V8: 745.66
S9: 45770 | T9: 2000838578 | U9: =V9/1.21 -> 714.85124 | V9: 864.97
S10: 45811 | T10: 2000857272 | U10: =V10/1.21 -> 616.24793 | V10: 745.66
S11: 45812 | T11: 2000857505 | U11: =V11/1.21 -> 536.34711 | V11: 648.98
S12: 45817 | T12: 2000857948 | U12: =V12/1.21 -> 517.65289 | V12: 626.36
S13: 45819 | T13: 2000859064 | U13: =V13/1.21 -> 536.34711 | V13: 648.98
S14: 45821 | T14: 2000859436 | U14: =V14/1.21 -> 536.34711 | V14: 648.98
S15: 45824 | T15: 2000859590 | U15: =V15/1.21 -> 568.65289 | V15: 688.07
S16: 45825 | T16: 2000859742 | U16: =V16/1.21 -> 568.65289 | V16: 688.07
S17: 45827 | T17: 2000860078 | U17: =V17/1.21 -> 437.75207 | V17: 529.68
... S27: 45937 | T27: 2000880051 | U27: =V27/1.21 -> 663 | V27: 802.23
S28: 46000 | T28: 2000916177 | U28: 2239.75 | V28: 2710.1
S29: 46000 | T29: 2000911936 | U29: 631,50521,90 | V29: 631.5
S30: 46000 | T30: 2000914177 | U30: 2543.2 | V30: 3077.27
I31: Celkem | U31: =SUM(U5:U30) -> 19120.38 | V31: =SUM(V5:V30) -> 23767.16
B32: S-401/75030926/2024 | C32: Rámcová smlouva na služby_Služby odtahování vozidel | D32: 28489969 | E32: Auto Prážák Assistance s r.o. | F32: 1990000 | G32: 2407900 | H32: 46561 | S32: 45950 | T32: 250101810 | U32: =V32/1.21 -> 3356 | V32: 4060.76 | W32: =F32-U177 -> 1194004 | X32: =G32-V177 -> 1444744.8
S33: 45950 | T33: 250101812 | U33: =V33/1.21 -> 3356 | V33: 4060.76
S34: 45952 | T34: 250101829 | U34: =V34/1.21 -> 6884 | V34: 8329.64
S35: 45959 | T35: 250101871 | U35: =V35/1.21 -> 3468 | V35: 4196.28
S36: 45959 | T36: 250101877 | U36: =V36/1.21 -> 5148 | V36: 6229.08
S37: 45959 | T37: 250101878 | U37: =V37/1.21 -> 6856 | V37: 8295.76
S38: 45959 | T38: 250101880 | U38: =V38/1.21 -> 7164 | V38: 8668.44
S39: 45964 | T39: 250101913 | U39: =V39/1.21 -> 4924 | V39: 5958.04
S40: 45964 | T40: 250101920 | U40: =V40/1.21 -> 4840 | V40: 5856.4
S41: 45971 | T41: 250101973 | U41: =V41/1.21 -> 5092 | V41: 6161.32
S42: 45973 | T42: 250102006 | U42: =V42/1.21 -> 5148 | V42: 6229.08
S43: 45973 | T43: 250102007 | U43: =V43/1.21 -> 5148 | V43: 6229.08
S44: 45973 | T44: 250102008 | U44: =V44/1.21 -> 2936 | V44: 3552.56
... S160: 45944 | T160: 250101757 | U160: =V160/1.21 -> 3524 | V160: 4264.04
S161: 46000 | T161: 250102212 | U161: 5176 | V161: 6262.96
S162: 46006 | T162: 250102346 | U162: 3440 | V162: 4162.4
S163: 46006 | T163: 250102342 | U163: 2460 | V163: 2976.6
S164: 46006 | T164: 250102340 | U164: 5120 | V164: 6195.2
S165: 46006 | T165: 250102274 | U165: 6604 | V165: 7990.84
S166: 46006 | T166: 250102273 | U166: 6604 | V166: 7990.84
...

Sheet OIT
B3: Číslo smlouvy | C3: Název | D3: IČO | E3: Partner | F3: Předpokládaná hodnota bez DPH | G3: Předpokládaná hodnota s DPH | H3: Platné do | J3: 2022 | M3: 2023 | P3: 2024 | S3: 2025 | V3: ZBÝVÁ
K4: bez DPH | L4: s DPH | N4: bez DPH | O4: s DPH | Q4: bez DPH | R4: s DPH | T4: bez DPH | U4: s DPH | V4: bez DPH | W4: s DPH
B5: S-363/75030926/22 | C5: Papír do termotiskáren | D5: 7524145 | E5: VTR Computers, s.r.o. | F5: 1990000 | G5: =1990000*1.21 -> 2407900 | H5: 46375 | M5: 45027 | N5: =20328*100/121 -> 16800 | O5: 20328 | P5: 45301 | Q5: =50820*100/121 -> 42000 | R5: 50820 | S5: 45693 | T5: =15246/121*100 -> 12600 | U5: 15246 | V5: =SUM(F5-N35-Q35-T35) -> 533440 | W5: =SUM(G5-O35-R35-U35) -> 645462.4
M6: 45042 | N6: =15246*100/121 -> 12600 | O6: 15246 | P6: 45309 | Q6: =15246*100/121 -> 12600 | R6: 15246 | S6: 45709 | T6: 12600 | U6: 15246
M7: 45042 | N7: =84361.2*100/121 -> 69720 | O7: 84361.2 | P7: 45309 | Q7: =15246*100/121 -> 12600 | R7: 15246 | S7: 45728 | T7: =84361.2/121*100 -> 69720 | U7: 84361.2
M8: 45044 | N8: =21344.4*100/121 -> 17640 | O8: 21344.4 | P8: 45310 | Q8: =40656*100/121 -> 33600 | R8: 40656 | S8: 45755 | T8: 12600 | U8: 15246
M9: 45064 | N9: =3049.2*100/121 -> 2520 | O9: 3049.2 | P9: 45320 | Q9: =17278.8*100/121 -> 14280 | R9: 17278.8 | S9: 45755 | T9: =U9/121*100 -> 14280 | U9: 17278.8
M10: 45079 | N10: =50820*100/121 -> 42000 | O10: 50820 | P10: 45365 | Q10: =30492*100/121 -> 25200 | R10: 30492 | S10: 45771 | T10: =U10*100/121 -> 25200 | U10: 30492
M11: 45091 | N11: =20328*100/121 -> 16800 | O11: 20328 | P11: 45393 | Q11: =15246*100/121 -> 12600 | R11: 15246 | S11: 45771 | T11: =U11*100/121 -> 20160 | U11: 24393.6
M12: 45093 | N12: =15246*100/121 -> 12600 | O12: 15246 | P12: 45414 | Q12: =15246*100/121 -> 12600 | R12: 15246 | S12: 45783 | T12: =U12*100/121 -> 14280 | U12: 17278.8
M13: 45093 | N13: =67082.4*100/121 -> 55440 | O13: 67082.4 | P13: 45415 | Q13: =24393.6*100/121 -> 20160 | R13: 24393.6 | S13: 45794 | T13: 12600 | U13: 15246
M14: 45097 | N14: =14229.6*100/121 -> 11760 | O14: 14229.6 | P14: 45419 | Q14: =17278.8*100/121 -> 14280 | R14: 17278.8 | S14: 45864 | T14: 12600 | U14: 15246
M15: 45099 | N15: =40656*100/121 -> 33600 | O15: 40656 | P15: 45435 | Q15: =17278.8*100/121 -> 14280 | R15: 17278.8 | S15: 45875 | T15: =U15/121*100 -> 14280 | U15: 17278.8
M16: 45111 | N16: =10164*100/121 -> 8400 | O16: 10164 | P16: 45450 | Q16: =67082.4*100/121 -> 55440 | R16: 67082.4 | S16: 45896 | T16: =U16/121*100 -> 25200 | U16: 30492
M17: 45140 | N17: =15246*100/121 -> 12600 | O17: 15246 | P17: 45483 | Q17: =15246*100/121 -> 12600 | R17: 15246 | S17: 45894 | T17: =U17/121*100 -> 12600 | U17: 15246
M18: 45170 | N18: =15246*100/121 -> 12600 | O18: 15246 | P18: 45484 | Q18: =50820*100/121 -> 42000 | R18: 50820 | S18: 45944 | T18: =U18/121*100 -> 14280 | U18: 17278.8
M19: 45170 | N19: =15246*100/121 -> 12600 | O19: 15246 | P19: 45518 | Q19: =17278.8*100/121 -> 14280 | R19: 17278.8 | S19: 45951 | T19: =U19/121*100 -> 20160 | U19: 24393.6
M20: 45170 | N20: =30492*100/121 -> 25200 | O20: 30492 | P20: 45518 | Q20: =15246*100/121 -> 12600 | R20: 15246 | S20: 45980 | T20: =U20/121*100 -> 14280 | U20: 17278.8
M21: 45184 | N21: =24393.6*100/121 -> 20160 | O21: 24393.6 | P21: 45576 | Q21: =30492*100/121 -> 25200 | R21: 30492 | S21: 46022 | T21: =U21/121*100 -> 115080 | U21: 139246.8
M22: 45198 | N22: =17278.8*100/121 -> 14280 | O22: 17278.8 | P22: 45587 | Q22: =40656*100/121 -> 33600 | R22: 40656
M23: 45239 | N23: =17278.8*100/121 -> 14280 | O23: 17278.8 | P23: 45594 | Q23: =24393.6*100/121 -> 20160 | R23: 24393.6
M24: 45259 | N24: =50820*100/121 -> 42000 | O24: 50820 | P24: 45597 | Q24: =17278.8*100/121 -> 14280 | R24: 17278.8
M25: 45266 | N25: =17278.8*100/121 -> 14280 | O25: 17278.8 | P25: 45602 | Q25: =15246*100/121 -> 12600 | R25: 15246
P26: 45607 | Q26: =15246*100/121 -> 12600 | R26: 15246
P27: 45607 | Q27: =77246.4*100/121 -> 63840 | R27: 77246.4
P28: 45625 | Q28: =7114.8*100/121 -> 5880 | R28: 7114.8
P29: 45635 | Q29: =17278.8*100/121 -> 14280 | R29: 17278.8
P30: 45643 | Q30: =15246*100/121 -> 12600 | R30: 15246
I35: Celkem | N35: =SUM(N5:N34) -> 467880 | O35: =SUM(O5:O34) -> 566134.8 | Q35: =SUM(Q5:Q34) -> 566160 | R35: =SUM(R5:R34) -> 685053.6 | T35: =SUM(T5:T34) -> 422520 | U35: =SUM(U5:U34) -> 511249.2
B36: S-023/75030926/23 | C36: Zajištění admin. a real. projektu Zajištění kyber. bezp. ZZS SK | D36: 4262719 | E36: TresTech, s.r.o. | F36: 1245000 | G36: 1506450 | H36: 2958465 | M36: 44988 | N36: =302500*100/121 -> 250000 | O36: 302500 | V36: =SUM(F36-N40) -> 797000 | W36: =SUM(G36-O40) -> 964370
M37: 45272 | N37: =239580*100/121 -> 198000 | O37: 239580
I40: Celkem | N40: =SUM(N36:N39) -> 448000 | O40: =SUM(O36:O39) -> 542080
B41: S-083/75030926/24 | C41: Zajištění konzultačních a poradenských služeb | D41: 4896661 | E41: Moore Technology CZ s.r.o. | F41: 1950000 | G41: 2359500 | H41: 46568 | V41: =SUM(F41-T45-Q98-T98-T54) -> 746836.81 | W41: =SUM(G41-U45-R98-U98-U54) -> 903672.54
I45: Celkem | T45: 0 | U45: 0
B46: S-083/75030926/24/02 | C46: Dílčí smlouva č. 2 k Rámcové dohodě S-083/75030926/24 | D46: 4896661 | E46: Moore Technology CZ s.r.o. | F46: 480000 | G46: 580800 | H46: 46568 | S46: 45903 | T46: =U46*100/121 -> 174382 | U46: 211002.22 | V46: =SUM(F46-Q54-T54) -> 305618 | W46: =SUM(G46-R54-U54) -> 369797.78
I54: Celkem | Q54: =SUM(Q46:Q53) -> 0 | R54: =SUM(R46:R53) -> 0 | T54: =SUM(T46:T53) -> 174382 | U54: =SUM(U46:U53) -> 211002.22
B55: S-369/75030926/2024 | C55: Rámcová dohoda na pořizování produktů Microsoft | D55: 24207519 | E55: SoftwareONE Czech Republic s.r.o. | F55: =26191541.32/121*100 -> 21645902 | G55: 26191541 | H55: 46721 | P55: 45627 | Q55: 7215300.6 | R55: 8730513.8 | V55: =SUM(F55-Q63) -> 14430601 | W55: =SUM(G55-R63) -> 17461028
I63: Celkem | Q63: 7215300.6 | R63: =SUM(R55:R62) -> 8730513.8
B64: S-369/75030926/2024/01 | C64: Prováděcí smlouva k Rámcové dohodě na pořizování produktů Microsoft | D64: 24207519 | E64: SoftwareONE Czech Republic s.r.o. | F64: =26191541.32/121*100 -> 21645902 | G64: 26191541 | H64: 46721 | S64: 45667 | T64: 7215300.6 | U64: 8730513.8 | V64: =SUM(F64-Q72-T72) -> 7738942.5 | W64: =SUM(G64-R72-U72) -> 9364120.4
S65: 45991 | T65: =U65*100/121 -> 6602494.3 | U65: 7989018.1
...

Sheet ÚŘe
B3: Číslo smlouvy | C3: Název | D3: IČO | E3: Partner | F3: Předpokládaná hodnota bez DPH | G3: Předpokládaná hodnota s DPH | H3: Platné do | J3: 2023 | M3: 2024 | P3: 2025 | S3: ZBÝVÁ
K4: bez DPH | L4: s DPH | N4: bez DPH | O4: s DPH | Q4: bez DPH | R4: s DPH | S4: bez DPH | T4: s DPH
A5: 1 | B5: S-008/75030926/24 | C5: Reklamní předměty | D5: 27190935 | E5: Arei reklamní předměty s.r.o. | F5: 650000 | G5: 786500 | H5: 46039 | M5: 45379 | N5: =26468.51*100/121 -> 21874.802 | O5: 26468.51 | P5: 45751 | Q5: =R5*100/121 -> 49130 | R5: 59447.3 | S5: =SUM(F5-N11-Q11) -> 37021.198 | T5: =SUM(G5-O11-R11) -> 44795.65
M6: 45379 | N6: =27530.52*100/121 -> 22752.496 | O6: 27530.52 | P6: 45833 | Q6: =R6*100/121 -> 96105 | R6: 116287.05
M7: 45474 | N7: =39466.57*100/121 -> 32617 | O7: 39466.57 | P7: 45911 | Q7: =R7*100/121 -> 267440 | R7: 323602.4
M8: 45520 | N8: =22276.1*100/121 -> 18410 | O8: 22276.1 | P8: 45966 | Q8: =R8*100/121 -> 60969.504 | R8: 73773.1
M9: 45643 | N9: =20727.3*100/121 -> 17130 | O9: 20727.3 | P9: 46030 | Q9: =R9*100/121 -> 26550 | R9: 32125.5
I11: Celkem | N11: =SUM(N5:N10) -> 112784.3 | O11: =SUM(O5:O10) -> 136469 | Q11: =SUM(Q5:Q10) -> 500194.5 | R11: =SUM(R5:R10) -> 605235.35
A12: 2
I16: Celkem
A17: 3
I21: Celkem
A22: 4
I25: Celkem
A26: 5
I34: Celkem

Sheet ZOS
B3: Číslo smlouvy | C3: Název | D3: IČO | E3: Partner | F3: Předpokládaná hodnota bez DPH | G3: Předpokládaná hodnota s DPH | H3: Platné do | J3: 2022 | M3: 2023 | P3: 2024 | S3: 2025 | V3: ZBÝVÁ
K4: bez DPH | L4: s DPH | N4: bez DPH | O4: s DPH | Q4: bez DPH | R4: s DPH | T4: bez DPH | U4: s DPH | V4: bez DPH | W4: s DPH
A5: 1
I11: Celkem
A12: 2
I16: Celkem
A17: 3
I21: Celkem
A22: 4
I25: Celkem
A26: 5
I34: Celkem

Sheet PKP
B3: Číslo smlouvy | C3: Název | D3: IČO | E3: Partner | F3: Předpokládaná hodnota bez DPH | G3: Předpokládaná hodnota s DPH | H3: Platné do | J3: 2022 | M3: 2023 | P3: 2024 | S3: 2025 | V3: ZBÝVÁ
K4: bez DPH | L4: s DPH | N4: bez DPH | O4: s DPH | Q4: bez DPH | R4: s DPH | T4: bez DPH | U4: s DPH | V4: bez DPH | W4: s DPH
A5: 1 | B5: S-076/75030926/2025 | C5: Rámcová smlouva o poskytování služeb_maskování figurantů | D5: 75063425 | E5: Oblastní spolek ČČK Kolín | G5: 150000 | H5: 46022 | S5: 45755 | U5: 5400 | W5: =G5-U11 -> 46500
S6: 45821 | U6: 35640
S7: 45959 | U7: 21600
S8: 46014 | U8: 40860
I11: Celkem | U11: =SUM(U5:U10) -> 103500
A12: 2
I16: Celkem
A17: 3
I21: Celkem
A22: 4
I26: Celkem
A27: 5
I35: Celkem

Sheet Souhrn všech plnění
B3: Číslo smlouvy | C3: Úsek | D3: Název | E3: IČO | F3: Partner | G3: Předpokládaná hodnota bez DPH | H3: Předpokládaná hodnota s DPH | I3: Platné do | J3: ZBÝVÁ
J4: bez DPH | K4: s DPH
B5: S-080/75030926/23 | C5: NNLZP | D5: BTK, Servis a náhradní díly pro defibrilátory Corpuls 3 | E5: 27094987 | F5: Cheirón, a.s. | G5: 1000080 | H5: 1210096.8 | I5: 46455 | J5: 420037.41 | K5: 508245.26
B6: S-269/75030926/2025 | C6: NNLZP | D6: Batohy pro výjezdové skupiny ZZS SK – část A | E6: 60719044 | F6: Vakuform, s.r.o. | G6: 850000 | H6: 1028500 | I6: 46470 | J6: 850000 | K6: 1028500
B7: S-270/75030926/2025 | C7: NNLZP | D7: Batohy pro výjezdové skupiny ZZS SK – část B | E7: 60719044 | F7: Vakuform, s.r.o. | G7: 500000 | H7: 605000 | I7: 46470 | J7: 500000 | K7: 605000
B8: S-265/75030926/24 | C8: NNLZP | D8: Dezinfekce II. | E8: 48586285 | F8: B. Braun Medical s.r.o. | G8: 1500000 | H8: 1815000 | I8: 46252 | J8: 1001598.2 | K8: 1211934.7
B9: S-265/75030926/22 | C9: NNLZP | D9: Fixační límce | E9: 27094987 | F9: Cheirón, a.s. | G9: 750000 | H9: 907500 | I9: 46299 | J9: 332307.83 | K9: 420429.14
B10: S-241/75030926/24 | C10: NNLZP | D10: Gravitační infuzní sety | E10: 27529053 | F10: POLYMED medical CZ, a.s. | G10: 700000 | H10: 784000 | I10: 46221 | J10: 319300 | K10: 357616
B11: S-199/75030926/2025 | C11: NNLZP | D11: Hadička spojovací | E11: 27529053 | F11: POLYMED medical CZ, a.s. | G11: 410000 | H11: 459200 | I11: 46198 | J11: 290000 | K11: 324800
B12: S-171/75030926/23 | C12: NNLZP | D12: Jednorázová prostěradla | E12: 25944991 | F12: MEDILAB ČR s.r.o. | G12: 1990000 | H12: 2407900 | I12: 46180 | J12: 674200 | K12: 922594
B13: S-045/75030926/2025 | C13: NNLZP | D13: Jednorázové elektrody - EKG | E13: 60491256 | F13: GPS Praha, spol. s r.o. | G13: 500000 | H13: 560000 | I13: 46078 | J13: 268160 | K13: 300339.2
B14: S-136/75030926/23 | C14: NNLZP | D14: Jednorázové přikrývky | E14: 28467299 | F14: Vivamed, s.r.o. | G14: 1990000 | H14: 2407900 | I14: 46157 | J14: 399000 | K14: 482790
B15: S-407/75030926/2024 | C15: NNLZP | D15: Intraoseální jehly II | E15: 47675934 | F15: Perfect Distribution a.s. | G15: 1500000 | H15: 1680000 | I15: 46034 | J15: 248162.95 | K15: 277942.5
B16: S-328/75030926/2025 | C16: NNLZP | D16: Intravenózní kanyly II. | E16: 25099019 | F16: PROMEDICA PRAHA GROUP, a.s. | G16: 1000000 | H16: 1120000 | I16: 46329 | J16: 878450 | K16: 983864
... B34: S-016/75030926/2025 | C34: EN | D34: Rámcová smlouva_Poskytování advokátních služeb III. | E34: 5732069 | F34: KAROLAS Legal s.r.o., advokátní kancelář | G34: 2000000 | H34: 2420000 | I34: 46781 | J34: 776200 | K34: 939202.5
B35: S-338/75030926/23 | C35: EN | D35: NPO_Sml o posk služeb_Komplex zajiš žád o dotaci v rámci výzvy 43 Kyber bez NPO MV | E35: 19573499 | F35: Mgr. Josef Trubáček | G35: =822800*100/121 -> 680000 | H35: 822800 | I35: 2958465 | J35: 118016.53 | K35: 142800
B36: S-340/75030926/2024 | C36: EN | D36: NPO_Rámcová smlouva_Právní podpora | E36: 5732069 | F36: KAROLAS Legal s.r.o., advokátní kancelář | G36: 624000 | H36: 755040 | I36: 46568 | J36: 89450 | K36: 108234.5
B37: S-353/75030926/2024 | C37: EN | D37: NPO_Rámcová smlouva na služby_technický dozor projektu Zajištění kyber. bezp. | E37: 24664812 | F37: DATASENSE s.r.o. | G37: 480000 | H37: 580800 | J37: 3200 | K37: 3872
B38: S-261/75030926/2025 | C38: EN | D38: NPO_Smlouva na služby_Zajištění kyb.bezpečnosti ZZS SK_realizace opatření ID008 | E38: 22302174 | F38: Cybrify, s.r.o. | G38: 948000 | H38: 1147080 | I38: 46173 | J38: 810000 | K38: 980100
B39: S-045/75030926/22 | C39: EN | D39: Smlouva o poskytování odbor. poradenství při admin. projektu financ. z ČR/EU | E39: 60724269 | F39: B&P Research, s.r.o. | G39: 480000 | H39: 580800 | I39: 46843 | J39: 269600 | K39: 326216
B40: S-204/75030926/22 | C40: EN | D40: Smlouva o posk. poradenství_žádost o dotaci a admin. projektu IROP 2021-2027 | E40: 60724269 | F40: B&P Research, s.r.o. | G40: 750000 | H40: 907500 | I40: 47848 | J40: 177000 | K40: 214170
B41: S-228/75030926/24 | C41: EN | D41: Zajištění služeb vyhledávání zaměstnanců | E41: 9692142 | F41: Moore Advisory CZ s.r.o. | G41: 1990000 | H41: 2407900 | I41: 46955 | J41: 1236669 | K41: 1496369.5
B42: S-250/75030926/2025 | C42: LN | D42: Rámcová dohoda_Infuzní roztoky IV_část A | E42: 48586285 | F42: B. Braun Medical s.r.o. | G42: 354879 | H42: 397464.48 | I42: 46606 | J42: 287655.63 | K42: 322174.31
B43: S-249/75030926/2025 | C43: LN | D43: Rámcová dohoda_Infuzní roztoky IV_část B | E43: 49689011 | F43: Baxter Czech spol. s r.o. | G43: 2328591 | H43: 2608021.9 | I43: 46606 | J43: 1896259.8 | K43: 2123811
B44: S-252/75030926/24 | C44: LN | D44: Léky III. | E44: 25277961 | F44: Interpharmac s.r.o. | G44: 5400000 | H44: 6048000 | I44: 46247 | J44: 1160380 | K44: 1299625.6
B45: S-384/75030926/2025 | C45: PN | D45: Smlouva na právní služby_poradenství v oblasti pracovního práva | E45: 29055130 | F45: Deloitte Legal s.r.o. | G45: 1500000 | H45: =1500000*1.21 -> 1815000 | I45: 2958465 | J45: 1436000 | K45: 1737560
B46: S-283/75030926/24 | C46: PTN | D46: Pneu, autodíly, autodoplňky, servisní služby | E46: 41193598 | F46: BestDrive Czech Republic, s.r.o. | G46: 50000 | H46: 60500 | I46: 47349 | J46: 30879.62 | K46: 36732.84
B47: S-401/75030926/2024 | C47: PTN | D47: Rámcová smlouva na služby_Služby odtahování vozidel | E47: 28489969 | F47: Auto Prážák Assistance s r.o. | G47: 1990000 | H47: 2407900 | I47: 46561 | J47: 1194004 | K47: 1444744.8
B48: S-077/75030926/24 | C48: PTN | D48: Smlouva o úklidových službách_Mladá Boleslav | E48: 4260431 | F48: KLM Security Group | G48: 450000 | H48: 544500 | I48: 46112 | J48: 154842.12 | K48: 187358.96
B49: S-196/75030926/21 | C49: PTN | D49: PD_Vybudování nového stanov. ZZS SK_Brandýs | E49: 68855958 | F49: Mgr. arch. Jaroslav Trávníček | G49: 1695000 | H49: =G49*1.21 -> 2050950 | I49: 46752 | J49: 1695000 | K49: 2050950
B50: S-187/75030926/22 | C50: PTN | D50: PD_Výstavba nového stanoviště ZZS SK_Benešov | E50: 68855958 | F50: Mgr. arch. Jaroslav Trávníček | G50: 1970000 | H50: 2383700 | I50: 46752 | J50: 298500 | K50: 361185
B51: S-239/75030926/22 | C51: PTN | D51: PD_Vybudování nového stanov. ZZS SK_Říčany | E51: 68855958 | F51: Mgr. arch. Jaroslav Trávníček | G51: 1365500 | H51: 1652255 | I51: 46752 | J51: 461869.67 | K51: 558863.2
B52: S-243/75030926/23 | C52: PTN | D52: PD_Výstavba nového stanoviště ZZS SK, Vlašim | E52: 68855958 | F52: Mgr. arch. Jaroslav Trávníček | G52: 1338500 | H52: 1619585 | I52: 46752 | J52: 445900.21 | K52: 539540
B53: S-245/75030926/23 | C53: PTN | D53: PD_Výstavba nového stanoviště ZZS SK, Český Brod | E53: 68855958 | F53: Mgr. arch. Jaroslav Trávníček | G53: 1344950 | H53: 1627390 | I53: 46752 | J53: 438680 | K53: 530804
B54: S-254/75030926/2025 | C54: PTN | D54: Stavebně-technická činnost ZZS SK 2025-2027_TDI | E54: 2891506 | F54: Easy CPM, s.r.o. | G54: 1150000 | H54: 1391500 | I54: 46752 | J54: 724953 | K54: 877193.13
B55: S-325/75030926/2025 | C55: PTN | D55: Rámcová kupní smlouva_Kancelářské potřeby a papírenské zboží pro ZZS SK | E55: 48111198 | F55: Activa spol. s r.o. | G55: 1900000 | H55: 2299000 | I55: 46682 | J55: 1756223.8 | K55: 2125031
B56: S-253/75030926/2025 | C56: PTN | D56: Rámcová kup. smlouva_Čistící prostředky a drogistické zboží pro ZZS SK | E56: 25347047 | F56: bika - velkoobchod papírem, sp | G56: 2900000 | H56: 3509000 | I56: 46627 | J56: 2793781.8 | K56: 3380475.9
B57: S-295/75030926/22 | C57: PTN | D57: Rámcová smlouva kupní a nájemní_MEDICINÁL. KYSLÍK PLYNNÝ VČ. NÁJMU.TL.LAHVÍ | E57: 11754 | F57: Linde Gas a.s. | G57: 27860600 | H57: 32789546 | I57: 46321 | J57: 27786554 | K57: 32184958
B58: S-363/75030926/22 | C58: IT | D58: Papír do termotiskáren | E58: 7524145 | F58: VTR Computers, s.r.o. | G58: 1990000 | H58: =1990000*1.21 -> 2407900 | I58: 46375 | J58: 533440 | K58: 645462.4
B59: S-023/75030926/23 | C59: IT | D59: Zajištění admin. a real. projektu Zajištění kyber. bezp. ZZS SK | E59: 4262719 | F59: TresTech, s.r.o. | G59: 1245000 | H59: 1506450 | I59: 2958465 | J59: 797000 | K59: 964370
...

Sheet Čerpání celkem
B1: Čerpání smluv po úsecích
B4: Úsek | D4: Nevyčerpáno (s DPH) | F4: Čerpáno 2025 (s DPH) | H4: Čerpáno 2024 (s DPH) | J4: Čerpáno 2023 (s DPH)
B6: ÚNLZP | D6: =SUM(ÚNLZP!W5:W1048576) -> 13495158 | F6: =SUMIF(ÚNLZP!I5:I1048576,"Celkem",ÚNLZP!U5:U1048576) -> 11539512 | H6: =SUMIF(ÚNLZP!I5:I1048576,"Celkem",ÚNLZP!R5:R1048576) -> 9075913.8 | J6: =SUMIF(ÚNLZP!I5:I1048576,"Celkem",ÚNLZP!O5:O1048576) -> 5026208.8
B7: ÚEKO | D7: =SUM(ÚEko!W5:W1048576) -> 14039118 | F7: =SUMIF(ÚEko!I5:I1048576,"Celkem",ÚEko!U5:U1048576) -> 6769471.3 | H7: =SUMIF(ÚEko!I5:I1048576,"Celkem",ÚEko!R5:R1048576) -> 3374739.2 | J7: =SUMIF(ÚEko!I5:I1048576,"Celkem",ÚEko!O5:O1048576) -> 317867
B8: ÚLE | D8: =SUM(ÚLé!T5:T1048576) -> 3972143.6 | F8: =SUMIF(ÚLé!I5:I1048576,"Celkem",ÚLé!R5:R1048576) -> 4634695.2 | H8: =SUMIF(ÚLé!I5:I1048576,"Celkem",ÚLé!O5:O1048576) -> 2330354.4 | J8: =SUMIF(ÚLé!I5:I1048576,"Celkem",ÚLé!L5:L1048576) -> 524193.19
B9: ÚPER | D9: =SUM(ÚPer!T5:T1048576) -> 2926696 | F9: =SUMIF(ÚPer!I5:I1048576,"Celkem",ÚPer!R5:R1048576) -> 1099072 | H9: =SUMIF(ÚPer!I5:I1048576,"Celkem",ÚPer!O5:O1048576) -> 239620 | J9: =SUMIF(ÚPer!I5:I1048576,"Celkem",ÚPer!L5:L1048576) -> 0
B10: ÚPT | D10: =SUM(ÚPT!X5:X1048576) -> 17304520 | F10: =SUMIF(ÚPT!I5:I1048576,"Celkem",ÚPT!V5:V1048576) -> 14793133 | H10: =SUMIF(ÚPT!I5:I1048576,"Celkem",ÚPT!R5:R1048576) -> 12504998 | J10: =SUMIF(ÚPT!I5:I1048576,"Celkem",ÚPT!O5:O1048576) -> 9060955.1
B11: OIT | D11: =SUM(OIT!W5:W1048576) -> 29715975 | F11: =SUMIF(OIT!I5:I1048576,"Celkem",OIT!U5:U1048576) -> 18381933 | H11: =SUMIF(OIT!I5:I1048576,"Celkem",OIT!R5:R1048576) -> 10129422 | J11: =SUMIF(OIT!I5:I1048576,"Celkem",OIT!O5:O1048576) -> 1108214.8
B12: ÚŘE | D12: =SUM(ÚŘe!T5:T1048576) -> 44795.65 | F12: =SUMIF(ÚŘe!I5:I1048576,"Celkem",ÚŘe!R5:R1048576) -> 605235.35 | H12: =SUMIF(ÚŘe!I5:I1048576,"Celkem",ÚŘe!O5:O1048576) -> 136469 | J12: =SUMIF(ÚŘe!I5:I1048576,"Celkem",ÚŘe!L5:L1048576) -> 0
B13: ZOS | D13: =SUM(ZOS!W5:W1048576) -> 0 | F13: =SUMIF(ZOS!I5:I1048576,"Celkem",ZOS!U5:U1048576) -> 0 | H13: =SUMIF(ZOS!I5:I1048576,"Celkem",ZOS!R5:R1048576) -> 0 | J13: =SUMIF(ZOS!I5:I1048576,"Celkem",ZOS!O5:O1048576) -> 0
B14: PKP | D14: =SUM(PKP!W5:W1048576) -> 46500 | F14: =SUMIF(PKP!I5:I1048576,"Celkem",PKP!U5:U1048576) -> 103500 | H14: =SUMIF(PKP!I5:I1048576,"Celkem",PKP!R5:R1048576) -> 0 | J14: =SUMIF(PKP!I5:I1048576,"Celkem",PKP!O5:O1048576) -> 0
D16: =SUM(D6:D15) -> 81544907 | F16: =SUM(F6:F15) -> 57926552 | H16: =SUM(H6:H15) -> 37791517 | J16: =SUM(J6:J15) -> 16037439

Sheet Končící smlouvy 2025
B2: Číslo smlouvy | C2: Název | D2: IČO | E2: Partner | F2: Předpokládaná hodnota bez DPH | G2: Předpokládaná hodnota s DPH | H2: Platné do | I2: ZBÝVÁ
H3: Platné do | I3: bez DPH | J3: s DPH
H4: celkem: | I4: =SUM(I5:I18) -> 4570537.2 | J4: =SUM(J5:J18) -> 5796187.7
B5: S-248/75030926/24 | C5: Smlouva o poskytování konzultačních a dalších souvisejících služeb | D5: 26746131 | E5: KTTP, s.r.o. | F5: 150000 | G5: 181500 | H5: 46022 | I5: 80781.188 | J5: 97745.15
B6: S-328/75030926/23 | C6: Testovací proužky do glukometru | D6: 6288740 | E6: LORMED s.r.o. | F6: 750000 | G6: 907500 | H6: 46008 | I6: 584628.1 | J6: 712620
B7: S-319/75030926/23 | C7: Ušní kloboučky k teploměrům | D7: 27777260 | E7: Lamipromed, s.r.o. | F7: 750000 | G7: 907500 | H7: 45974 | I7: 622000 | J7: 761260
B8: S-321/75030926/23 | C8: Intravenózní kanyly | D8: 25099019 | E8: PROMEDICA PRAHA GROUP, a.s. | F8: 1839540 | G8: 2225843.4 | H8: 45969 | I8: 555840 | J8: 759258.9
B9: S-312/75030926/23 | C9: Adaptéry ke kapnografu EMMA | D9: 27301800 | E9: LHL, s.r.o. | F9: 750000 | G9: 907500 | H9: 45967 | I9: 320980 | J9: 426998
B10: S-145/75030926/23 | C10: Infuzní roztoky II. | D10: 19010290 | E10: Pharmos, a.s. | F10: 1990000 | G10: 2407900 | H10: 45830 | I10: 338374.72 | J10: 409433.39
B11: S-185/75030926/23 | C11: Smlouva - audit ročních účetních závěrek 2023-2024 | D11: 27922677 | E11: Bene Factum, a.s. | F11: 438000 | G11: 529980 | H11: 45821 | I11: 153300 | J11: 185493
B12: S-147/75030926/23 | C12: Smlouva o poskytování poradenských a konzultačních služeb | D12: 29268931 | E12: Alter Audit, s.r.o. | F12: 500000 | G12: 605000 | H12: 45812 | I12: 115700 | J12: 139997
B13: S-137/75030926/23 | C13: Jednorázový povlak na deku - 2 | D13: 28467299 | E13: Vivamed, s.r.o. | F13: 490000 | G13: 592900 | H13: 45792 | I13: 105000 | J13: 127050
B14: S-111/75030926/23 | C14: Rouška na popáleniny chladící | D14: 26698293 | E14: INTERCARE s.r.o. | F14: 490000 | G14: 563500 | H14: 45763 | I14: 121300 | J14: 121300
B15: S-098/75030926/23 | C15: Rukavice | D15: 25099019 | E15: PROMEDICA PRAHA GROUP, a.s. | F15: 1990000 | G15: 2407900 | H15: 45743 | I15: 312440 | J15: 459387.2
B16: S-063/75030926/23 | C16: Intraoseální jehly s příslušenstvím | D16: 28849809 | E16: Teleflex Medical s.r.o. | F16: 1990000 | G16: 2407900 | H16: 45725 | I16: 4421.69 | J16: 76160.71
... B18: S-057/75030926/23 | C18: Hadička spojovací | D18: 27529053 | E18: POLYMED medical CZ, a.s. | F18: 490000 | G18: 592900 | H18: 45715 | I18: 1255771.5 | J18: 1519484.4
